[2023-10-21T15:40:32.944+0000] {taskinstance.py:1157} INFO - Dependencies all met for dep_context=non-requeueable deps ti=<TaskInstance: etl_day18.merge_dataframes manual__2023-10-21T15:40:25.006586+00:00 [queued]>
[2023-10-21T15:40:32.963+0000] {taskinstance.py:1157} INFO - Dependencies all met for dep_context=requeueable deps ti=<TaskInstance: etl_day18.merge_dataframes manual__2023-10-21T15:40:25.006586+00:00 [queued]>
[2023-10-21T15:40:32.964+0000] {taskinstance.py:1359} INFO - Starting attempt 1 of 1
[2023-10-21T15:40:33.042+0000] {taskinstance.py:1380} INFO - Executing <Task(PythonOperator): merge_dataframes> on 2023-10-21 15:40:25.006586+00:00
[2023-10-21T15:40:33.051+0000] {standard_task_runner.py:57} INFO - Started process 4334 to run task
[2023-10-21T15:40:33.065+0000] {standard_task_runner.py:84} INFO - Running: ['***', 'tasks', 'run', 'etl_day18', 'merge_dataframes', 'manual__2023-10-21T15:40:25.006586+00:00', '--job-id', '58', '--raw', '--subdir', 'DAGS_FOLDER/ETL_day18.py', '--cfg-path', '/tmp/tmpj67zm9se']
[2023-10-21T15:40:33.080+0000] {standard_task_runner.py:85} INFO - Job 58: Subtask merge_dataframes
[2023-10-21T15:40:33.210+0000] {task_command.py:415} INFO - Running <TaskInstance: etl_day18.merge_dataframes manual__2023-10-21T15:40:25.006586+00:00 [running]> on host 90cf752d844d
[2023-10-21T15:40:33.611+0000] {taskinstance.py:1660} INFO - Exporting env vars: AIRFLOW_CTX_DAG_OWNER='kel11' AIRFLOW_CTX_DAG_ID='etl_day18' AIRFLOW_CTX_TASK_ID='merge_dataframes' AIRFLOW_CTX_EXECUTION_DATE='2023-10-21T15:40:25.006586+00:00' AIRFLOW_CTX_TRY_NUMBER='1' AIRFLOW_CTX_DAG_RUN_ID='manual__2023-10-21T15:40:25.006586+00:00'
[2023-10-21T15:40:33.712+0000] {taskinstance.py:1935} ERROR - Task failed with exception
Traceback (most recent call last):
  File "/home/airflow/.local/lib/python3.8/site-packages/airflow/operators/python.py", line 192, in execute
    return_value = self.execute_callable()
  File "/home/airflow/.local/lib/python3.8/site-packages/airflow/operators/python.py", line 209, in execute_callable
    return self.python_callable(*self.op_args, **self.op_kwargs)
  File "/opt/airflow/dags/ETL_day18.py", line 78, in merge_dataframes
    merged_df = pd.concat([latest_df, exist_data_psql])
  File "/home/airflow/.local/lib/python3.8/site-packages/pandas/core/reshape/concat.py", line 372, in concat
    op = _Concatenator(
  File "/home/airflow/.local/lib/python3.8/site-packages/pandas/core/reshape/concat.py", line 452, in __init__
    raise ValueError("All objects passed were None")
ValueError: All objects passed were None
[2023-10-21T15:40:33.782+0000] {taskinstance.py:1398} INFO - Marking task as FAILED. dag_id=etl_day18, task_id=merge_dataframes, execution_date=20231021T154025, start_date=20231021T154032, end_date=20231021T154033
[2023-10-21T15:40:33.925+0000] {standard_task_runner.py:104} ERROR - Failed to execute job 58 for task merge_dataframes (All objects passed were None; 4334)
[2023-10-21T15:40:33.973+0000] {local_task_job_runner.py:228} INFO - Task exited with return code 1
[2023-10-21T15:40:34.067+0000] {taskinstance.py:2776} INFO - 0 downstream tasks scheduled from follow-on schedule check
