[2023-10-21T15:17:13.556+0000] {taskinstance.py:1157} INFO - Dependencies all met for dep_context=non-requeueable deps ti=<TaskInstance: etl_day18.extract_rows manual__2023-10-21T15:17:06.088041+00:00 [queued]>
[2023-10-21T15:17:13.570+0000] {taskinstance.py:1157} INFO - Dependencies all met for dep_context=requeueable deps ti=<TaskInstance: etl_day18.extract_rows manual__2023-10-21T15:17:06.088041+00:00 [queued]>
[2023-10-21T15:17:13.570+0000] {taskinstance.py:1359} INFO - Starting attempt 1 of 1
[2023-10-21T15:17:13.590+0000] {taskinstance.py:1380} INFO - Executing <Task(PythonOperator): extract_rows> on 2023-10-21 15:17:06.088041+00:00
[2023-10-21T15:17:13.598+0000] {standard_task_runner.py:57} INFO - Started process 3870 to run task
[2023-10-21T15:17:13.603+0000] {standard_task_runner.py:84} INFO - Running: ['***', 'tasks', 'run', 'etl_day18', 'extract_rows', 'manual__2023-10-21T15:17:06.088041+00:00', '--job-id', '28', '--raw', '--subdir', 'DAGS_FOLDER/ETL_day18.py', '--cfg-path', '/tmp/tmpydki9uf4']
[2023-10-21T15:17:13.606+0000] {standard_task_runner.py:85} INFO - Job 28: Subtask extract_rows
[2023-10-21T15:17:13.657+0000] {task_command.py:415} INFO - Running <TaskInstance: etl_day18.extract_rows manual__2023-10-21T15:17:06.088041+00:00 [running]> on host 90cf752d844d
[2023-10-21T15:17:13.752+0000] {taskinstance.py:1660} INFO - Exporting env vars: AIRFLOW_CTX_DAG_OWNER='kel11' AIRFLOW_CTX_DAG_ID='etl_day18' AIRFLOW_CTX_TASK_ID='extract_rows' AIRFLOW_CTX_EXECUTION_DATE='2023-10-21T15:17:06.088041+00:00' AIRFLOW_CTX_TRY_NUMBER='1' AIRFLOW_CTX_DAG_RUN_ID='manual__2023-10-21T15:17:06.088041+00:00'
[2023-10-21T15:17:13.798+0000] {taskinstance.py:1935} ERROR - Task failed with exception
Traceback (most recent call last):
  File "/home/airflow/.local/lib/python3.8/site-packages/airflow/operators/python.py", line 192, in execute
    return_value = self.execute_callable()
  File "/home/airflow/.local/lib/python3.8/site-packages/airflow/operators/python.py", line 209, in execute_callable
    return self.python_callable(*self.op_args, **self.op_kwargs)
  File "/opt/airflow/dags/ETL_day18.py", line 49, in transform_data
    df['lastUpdated'] = df['lastUpdated'].dt.tz_localize('UTC')
  File "/home/airflow/.local/lib/python3.8/site-packages/pandas/core/accessor.py", line 112, in f
    return self._delegate_method(name, *args, **kwargs)
  File "/home/airflow/.local/lib/python3.8/site-packages/pandas/core/indexes/accessors.py", line 128, in _delegate_method
    result = method(*args, **kwargs)
  File "/home/airflow/.local/lib/python3.8/site-packages/pandas/core/indexes/datetimes.py", line 279, in tz_localize
    arr = self._data.tz_localize(tz, ambiguous, nonexistent)
  File "/home/airflow/.local/lib/python3.8/site-packages/pandas/core/arrays/_mixins.py", line 86, in method
    return meth(self, *args, **kwargs)
  File "/home/airflow/.local/lib/python3.8/site-packages/pandas/core/arrays/datetimes.py", line 1035, in tz_localize
    raise TypeError("Already tz-aware, use tz_convert to convert.")
TypeError: Already tz-aware, use tz_convert to convert.
[2023-10-21T15:17:13.812+0000] {taskinstance.py:1398} INFO - Marking task as FAILED. dag_id=etl_day18, task_id=extract_rows, execution_date=20231021T151706, start_date=20231021T151713, end_date=20231021T151713
[2023-10-21T15:17:13.826+0000] {standard_task_runner.py:104} ERROR - Failed to execute job 28 for task extract_rows (Already tz-aware, use tz_convert to convert.; 3870)
[2023-10-21T15:17:13.871+0000] {local_task_job_runner.py:228} INFO - Task exited with return code 1
[2023-10-21T15:17:13.928+0000] {taskinstance.py:2776} INFO - 0 downstream tasks scheduled from follow-on schedule check
