[2023-10-21T15:29:08.816+0000] {taskinstance.py:1157} INFO - Dependencies all met for dep_context=non-requeueable deps ti=<TaskInstance: etl_day18.merge_dataframes manual__2023-10-21T15:28:53.311855+00:00 [queued]>
[2023-10-21T15:29:08.831+0000] {taskinstance.py:1157} INFO - Dependencies all met for dep_context=requeueable deps ti=<TaskInstance: etl_day18.merge_dataframes manual__2023-10-21T15:28:53.311855+00:00 [queued]>
[2023-10-21T15:29:08.831+0000] {taskinstance.py:1359} INFO - Starting attempt 1 of 1
[2023-10-21T15:29:08.851+0000] {taskinstance.py:1380} INFO - Executing <Task(PythonOperator): merge_dataframes> on 2023-10-21 15:28:53.311855+00:00
[2023-10-21T15:29:08.860+0000] {standard_task_runner.py:57} INFO - Started process 4089 to run task
[2023-10-21T15:29:08.865+0000] {standard_task_runner.py:84} INFO - Running: ['***', 'tasks', 'run', 'etl_day18', 'merge_dataframes', 'manual__2023-10-21T15:28:53.311855+00:00', '--job-id', '41', '--raw', '--subdir', 'DAGS_FOLDER/ETL_day18.py', '--cfg-path', '/tmp/tmpdvl_7gzn']
[2023-10-21T15:29:08.869+0000] {standard_task_runner.py:85} INFO - Job 41: Subtask merge_dataframes
[2023-10-21T15:29:08.926+0000] {task_command.py:415} INFO - Running <TaskInstance: etl_day18.merge_dataframes manual__2023-10-21T15:28:53.311855+00:00 [running]> on host 90cf752d844d
[2023-10-21T15:29:09.011+0000] {taskinstance.py:1660} INFO - Exporting env vars: AIRFLOW_CTX_DAG_OWNER='kel11' AIRFLOW_CTX_DAG_ID='etl_day18' AIRFLOW_CTX_TASK_ID='merge_dataframes' AIRFLOW_CTX_EXECUTION_DATE='2023-10-21T15:28:53.311855+00:00' AIRFLOW_CTX_TRY_NUMBER='1' AIRFLOW_CTX_DAG_RUN_ID='manual__2023-10-21T15:28:53.311855+00:00'
[2023-10-21T15:29:09.071+0000] {taskinstance.py:1935} ERROR - Task failed with exception
Traceback (most recent call last):
  File "/home/airflow/.local/lib/python3.8/site-packages/airflow/operators/python.py", line 192, in execute
    return_value = self.execute_callable()
  File "/home/airflow/.local/lib/python3.8/site-packages/airflow/operators/python.py", line 209, in execute_callable
    return self.python_callable(*self.op_args, **self.op_kwargs)
  File "/opt/airflow/dags/ETL_day18.py", line 77, in merge_dataframes
    merged_df = pd.merge(exist_data_psql, latest_df)
  File "/home/airflow/.local/lib/python3.8/site-packages/pandas/core/reshape/merge.py", line 148, in merge
    op = _MergeOperation(
  File "/home/airflow/.local/lib/python3.8/site-packages/pandas/core/reshape/merge.py", line 741, in __init__
    self._maybe_coerce_merge_keys()
  File "/home/airflow/.local/lib/python3.8/site-packages/pandas/core/reshape/merge.py", line 1405, in _maybe_coerce_merge_keys
    raise ValueError(msg)
ValueError: You are trying to merge on datetime64[ns] and object columns. If you wish to proceed you should use pd.concat
[2023-10-21T15:29:09.082+0000] {taskinstance.py:1398} INFO - Marking task as FAILED. dag_id=etl_day18, task_id=merge_dataframes, execution_date=20231021T152853, start_date=20231021T152908, end_date=20231021T152909
[2023-10-21T15:29:09.096+0000] {standard_task_runner.py:104} ERROR - Failed to execute job 41 for task merge_dataframes (You are trying to merge on datetime64[ns] and object columns. If you wish to proceed you should use pd.concat; 4089)
[2023-10-21T15:29:09.127+0000] {local_task_job_runner.py:228} INFO - Task exited with return code 1
[2023-10-21T15:29:09.156+0000] {taskinstance.py:2776} INFO - 0 downstream tasks scheduled from follow-on schedule check
