[2023-10-22T08:37:10.318+0000] {taskinstance.py:1157} INFO - Dependencies all met for dep_context=non-requeueable deps ti=<TaskInstance: etl_day18.load_dataframe_into_postgresql manual__2023-10-22T08:36:53.657614+00:00 [queued]>
[2023-10-22T08:37:10.333+0000] {taskinstance.py:1157} INFO - Dependencies all met for dep_context=requeueable deps ti=<TaskInstance: etl_day18.load_dataframe_into_postgresql manual__2023-10-22T08:36:53.657614+00:00 [queued]>
[2023-10-22T08:37:10.333+0000] {taskinstance.py:1359} INFO - Starting attempt 1 of 1
[2023-10-22T08:37:10.350+0000] {taskinstance.py:1380} INFO - Executing <Task(PythonOperator): load_dataframe_into_postgresql> on 2023-10-22 08:36:53.657614+00:00
[2023-10-22T08:37:10.356+0000] {standard_task_runner.py:57} INFO - Started process 434 to run task
[2023-10-22T08:37:10.362+0000] {standard_task_runner.py:84} INFO - Running: ['***', 'tasks', 'run', 'etl_day18', 'load_dataframe_into_postgresql', 'manual__2023-10-22T08:36:53.657614+00:00', '--job-id', '160', '--raw', '--subdir', 'DAGS_FOLDER/ETL_day18.py', '--cfg-path', '/tmp/tmp83h9rfl_']
[2023-10-22T08:37:10.366+0000] {standard_task_runner.py:85} INFO - Job 160: Subtask load_dataframe_into_postgresql
[2023-10-22T08:37:10.421+0000] {task_command.py:415} INFO - Running <TaskInstance: etl_day18.load_dataframe_into_postgresql manual__2023-10-22T08:36:53.657614+00:00 [running]> on host 90cf752d844d
[2023-10-22T08:37:10.520+0000] {taskinstance.py:1660} INFO - Exporting env vars: AIRFLOW_CTX_DAG_OWNER='kel11' AIRFLOW_CTX_DAG_ID='etl_day18' AIRFLOW_CTX_TASK_ID='load_dataframe_into_postgresql' AIRFLOW_CTX_EXECUTION_DATE='2023-10-22T08:36:53.657614+00:00' AIRFLOW_CTX_TRY_NUMBER='1' AIRFLOW_CTX_DAG_RUN_ID='manual__2023-10-22T08:36:53.657614+00:00'
[2023-10-22T08:37:10.603+0000] {base.py:73} INFO - Using connection ID 'postgresql_db' for task execution.
[2023-10-22T08:37:10.605+0000] {logging_mixin.py:151} INFO - Engine(postgresql://diwahsap:***@ep-falling-leaf-21500535.ap-southeast-1.aws.neon.tech:5432/dibimbing?__extra__=%7B%7D)
[2023-10-22T08:37:12.703+0000] {taskinstance.py:1935} ERROR - Task failed with exception
Traceback (most recent call last):
  File "/home/airflow/.local/lib/python3.8/site-packages/airflow/operators/python.py", line 192, in execute
    return_value = self.execute_callable()
  File "/home/airflow/.local/lib/python3.8/site-packages/airflow/operators/python.py", line 209, in execute_callable
    return self.python_callable(*self.op_args, **self.op_kwargs)
  File "/opt/airflow/dags/ETL_day18.py", line 101, in load_dataframe_into_postgresql
    df.to_sql('public.latest',
  File "/home/airflow/.local/lib/python3.8/site-packages/pandas/core/generic.py", line 2878, in to_sql
    return sql.to_sql(
  File "/home/airflow/.local/lib/python3.8/site-packages/pandas/io/sql.py", line 769, in to_sql
    return pandas_sql.to_sql(
  File "/home/airflow/.local/lib/python3.8/site-packages/pandas/io/sql.py", line 1910, in to_sql
    table = self.prep_table(
  File "/home/airflow/.local/lib/python3.8/site-packages/pandas/io/sql.py", line 1802, in prep_table
    raise ValueError(f"The type of {col} is not a SQLAlchemy type")
ValueError: The type of location is not a SQLAlchemy type
[2023-10-22T08:37:12.718+0000] {taskinstance.py:1398} INFO - Marking task as FAILED. dag_id=etl_day18, task_id=load_dataframe_into_postgresql, execution_date=20231022T083653, start_date=20231022T083710, end_date=20231022T083712
[2023-10-22T08:37:12.734+0000] {standard_task_runner.py:104} ERROR - Failed to execute job 160 for task load_dataframe_into_postgresql (The type of location is not a SQLAlchemy type; 434)
[2023-10-22T08:37:12.766+0000] {local_task_job_runner.py:228} INFO - Task exited with return code 1
[2023-10-22T08:37:12.786+0000] {taskinstance.py:2776} INFO - 0 downstream tasks scheduled from follow-on schedule check
