[2023-10-21T16:12:24.187+0000] {taskinstance.py:1157} INFO - Dependencies all met for dep_context=non-requeueable deps ti=<TaskInstance: etl_day18.load_dataframe_into_postgresql manual__2023-10-21T16:12:07.587269+00:00 [queued]>
[2023-10-21T16:12:24.201+0000] {taskinstance.py:1157} INFO - Dependencies all met for dep_context=requeueable deps ti=<TaskInstance: etl_day18.load_dataframe_into_postgresql manual__2023-10-21T16:12:07.587269+00:00 [queued]>
[2023-10-21T16:12:24.202+0000] {taskinstance.py:1359} INFO - Starting attempt 1 of 1
[2023-10-21T16:12:24.218+0000] {taskinstance.py:1380} INFO - Executing <Task(PythonOperator): load_dataframe_into_postgresql> on 2023-10-21 16:12:07.587269+00:00
[2023-10-21T16:12:24.225+0000] {standard_task_runner.py:57} INFO - Started process 5036 to run task
[2023-10-21T16:12:24.229+0000] {standard_task_runner.py:84} INFO - Running: ['***', 'tasks', 'run', 'etl_day18', 'load_dataframe_into_postgresql', 'manual__2023-10-21T16:12:07.587269+00:00', '--job-id', '110', '--raw', '--subdir', 'DAGS_FOLDER/ETL_day18.py', '--cfg-path', '/tmp/tmpt0075mzy']
[2023-10-21T16:12:24.233+0000] {standard_task_runner.py:85} INFO - Job 110: Subtask load_dataframe_into_postgresql
[2023-10-21T16:12:24.298+0000] {task_command.py:415} INFO - Running <TaskInstance: etl_day18.load_dataframe_into_postgresql manual__2023-10-21T16:12:07.587269+00:00 [running]> on host 90cf752d844d
[2023-10-21T16:12:24.415+0000] {taskinstance.py:1660} INFO - Exporting env vars: AIRFLOW_CTX_DAG_OWNER='kel11' AIRFLOW_CTX_DAG_ID='etl_day18' AIRFLOW_CTX_TASK_ID='load_dataframe_into_postgresql' AIRFLOW_CTX_EXECUTION_DATE='2023-10-21T16:12:07.587269+00:00' AIRFLOW_CTX_TRY_NUMBER='1' AIRFLOW_CTX_DAG_RUN_ID='manual__2023-10-21T16:12:07.587269+00:00'
[2023-10-21T16:12:24.470+0000] {taskinstance.py:1935} ERROR - Task failed with exception
Traceback (most recent call last):
  File "/home/airflow/.local/lib/python3.8/site-packages/airflow/operators/python.py", line 192, in execute
    return_value = self.execute_callable()
  File "/home/airflow/.local/lib/python3.8/site-packages/airflow/operators/python.py", line 209, in execute_callable
    return self.python_callable(*self.op_args, **self.op_kwargs)
  File "/opt/airflow/dags/ETL_day18.py", line 104, in load_dataframe_into_postgresql
    engine = create_engine(f'postgresql://{username}:{password}@{host}:{port}/{database}')
NameError: name 'port' is not defined
[2023-10-21T16:12:24.483+0000] {taskinstance.py:1398} INFO - Marking task as FAILED. dag_id=etl_day18, task_id=load_dataframe_into_postgresql, execution_date=20231021T161207, start_date=20231021T161224, end_date=20231021T161224
[2023-10-21T16:12:24.500+0000] {standard_task_runner.py:104} ERROR - Failed to execute job 110 for task load_dataframe_into_postgresql (name 'port' is not defined; 5036)
[2023-10-21T16:12:24.532+0000] {local_task_job_runner.py:228} INFO - Task exited with return code 1
[2023-10-21T16:12:24.576+0000] {taskinstance.py:2776} INFO - 0 downstream tasks scheduled from follow-on schedule check
